Workbook
Name I: DES 'LISTE DES ELEVES'!$A$3:$A$10
Name LISTE: 'LISTE DES ELEVES'!$A$3:$A$7
Name NOM: 'LISTE DES ELEVES'!$A$21

Sheet Feuil1
A1: REPUBLIQUE DEMOCRATIQUE DU CONGO
A2: MINISTERE DE L'EDUCATION NATIONALE ET NOUVELLE CITOYENNETE
A3: N°ID
A4: PROVINCE KWILU
A5: ECOLE : I.T.P MOSALA | F5: NOM ET POST-NOM : | I5: KAPALATI MAYIMI | N5: =IF(I5<>"",VLOOKUP(I5,'LISTE DES ELEVES'!A3:DQ100,2,FALSE)) -> M
A6: VILLE : BANDUNDU | F6: NE (E)………………………LE …./……./……… | G6: =IF(I5<>"",VLOOKUP(I5,'LISTE DES ELEVES'!A3:DQ100,3,FALSE)) -> BANDUNDU,Le 23/07/2007
A7: COMMUNE / TER (1) : BASOKO | F7: CLASSE………………………………………………. | G7: =IF(I5<>"",VLOOKUP(I5,'LISTE DES ELEVES'!A3:DQ100,4,FALSE)) -> 3ème ELELECT
A8: CODE | F8: N° PERM. :
A9: BULLETIN DE LA 3éme HUMANITE ELECTRICITE ANNEE SCOLAIRE 2025 - 2026
A10: BRANCHES | B10: PREMIER SEMESTRE | F10: SECOND SEMESTRE | J10: T.G | L10: EXAM DE R
B11: TR. JOURNAL | D11: EXAM | E11: TOT | F11: TR. JOURNAL | H11: EXAM | I11: TOT
B12: 1ère P | C12: 2e P | F12: 3ère P | G12: 4éP | L12: ‰ | M12: SIGN. P
A13: MAXIMA | B13: 10 | C13: 10 | D13: 20 | E13: 40 | F13: 10 | G13: 10 | H13: 20 | I13: 40 | J13: 80
A14: ='LISTE DES ELEVES'!F1 -> RELIGION | B14: =IF(I5<>"",VLOOKUP(I5,'LISTE DES ELEVES'!A3:DQ100,6,FALSE)) -> 3 | C14: =IF(I5<>"",VLOOKUP(I5,'LISTE DES ELEVES'!A3:DQ100,7,FALSE)) -> 0 | D14: =IF(I5<>"",VLOOKUP(I5,'LISTE DES ELEVES'!A3:DQ100,8,FALSE)) -> 0 | E14: =B14+C14+D14 -> 3 | F14: =IF(I5<>"",VLOOKUP(I5,'LISTE DES ELEVES'!A3:DQ100,9,FALSE)) -> 0 | G14: =IF(I5<>"",VLOOKUP(I5,'LISTE DES ELEVES'!A3:DQ100,10,FALSE)) -> 0 | H14: =IF(I5<>"",VLOOKUP(I5,'LISTE DES ELEVES'!A3:DQ100,11,FALSE)) -> 0 | I14: =F14+G14+H14 -> 0 | J14: =E14+I14 -> 3
A15: ='LISTE DES ELEVES'!L1 -> CIVISME | B15: =IF(I5<>"",VLOOKUP(I5,'LISTE DES ELEVES'!A3:DQ100,12,FALSE)) -> 4 | C15: =IF(I5<>"",VLOOKUP(I5,'LISTE DES ELEVES'!A3:DQ100,13,FALSE)) -> 0 | D15: =IF(I5<>"",VLOOKUP(I5,'LISTE DES ELEVES'!A3:DQ100,14,FALSE)) -> 0 | E15: =B15+C15+D15 -> 4 | F15: =IF(I5<>"",VLOOKUP(I5,'LISTE DES ELEVES'!A3:DQ100,15,FALSE)) -> 0 | G15: =IF(I5<>"",VLOOKUP(I5,'LISTE DES ELEVES'!A3:DQ100,16,FALSE)) -> 0 | H15: =IF(I5<>"",VLOOKUP(I5,'LISTE DES ELEVES'!A3:DQ100,17,FALSE)) -> 0 | I15: =F15+G14+H15 -> 0 | J15: =E15+I15 -> 4
A16: ='LISTE DES ELEVES'!R1 -> EDUCATION A LA VIE | B16: =IF(I5<>"",VLOOKUP(I5,'LISTE DES ELEVES'!A3:DQ100,18,FALSE)) -> 6 | C16: =IF(I5<>"",VLOOKUP(I5,'LISTE DES ELEVES'!A3:DQ100,19,FALSE)) -> 0 | D16: =IF(I5<>"",VLOOKUP(I5,'LISTE DES ELEVES'!A3:DQ100,20,FALSE)) -> 0 | E16: =B16+C16+D16 -> 6 | F16: =IF(I5<>"",VLOOKUP(I5,'LISTE DES ELEVES'!A3:DQ100,21,FALSE)) -> 0 | G16: =IF(I5<>"",VLOOKUP(I5,'LISTE DES ELEVES'!A3:DQ100,22,FALSE)) -> 0 | H16: =IF(I5<>"",VLOOKUP(I5,'LISTE DES ELEVES'!A3:DQ100,23,FALSE)) -> 0 | I16: =F16+G15+H16 -> 0 | J16: =E16+I16 -> 6
A17: MAXIMA | B17: 20 | C17: 20 | D17: 40 | E17: 80 | F17: 20 | G17: 20 | H17: 40 | I17: 80 | J17: 160
A18: ='LISTE DES ELEVES'!X1 -> ANGLAIS | B18: =IF(I5<>"",VLOOKUP(I5,'LISTE DES ELEVES'!A3:DQ100,24,FALSE)) -> 13 | C18: =IF(I5<>"",VLOOKUP(I5,'LISTE DES ELEVES'!A3:DQ100,25,FALSE)) -> 0 | D18: =IF(I5<>"",VLOOKUP(I5,'LISTE DES ELEVES'!A3:DQ100,26,FALSE)) -> 0 | E18: =B18+C18+D18 -> 13 | F18: =IF(I5<>"",VLOOKUP(I5,'LISTE DES ELEVES'!A3:DQ100,27,FALSE)) -> 0 | G18: =IF(I5<>"",VLOOKUP(I5,'LISTE DES ELEVES'!A3:DQ100,28,FALSE)) -> 0 | H18: =IF(I5<>"",VLOOKUP(I5,'LISTE DES ELEVES'!A3:DQ100,29,FALSE)) -> 0 | I18: =F18+G18+H18 -> 0 | J18: =E18+I18 -> 13
A19: ='LISTE DES ELEVES'!AD1 -> INFORMATIQUE | B19: =IF(I5<>"",VLOOKUP(I5,'LISTE DES ELEVES'!A3:DQ100,30,FALSE)) -> 13 | C19: =IF(I5<>"",VLOOKUP(I5,'LISTE DES ELEVES'!A3:DQ100,31,FALSE)) -> 0 | D19: =IF(I5<>"",VLOOKUP(I5,'LISTE DES ELEVES'!A3:DQ100,32,FALSE)) -> 0 | E19: =B19+C19+D19 -> 13 | F19: =IF(I5<>"",VLOOKUP(I5,'LISTE DES ELEVES'!A3:DQ100,33,FALSE)) -> 0 | G19: =IF(I5<>"",VLOOKUP(I5,'LISTE DES ELEVES'!A3:DQ100,34,FALSE)) -> 0 | H19: =IF(I5<>"",VLOOKUP(I5,'LISTE DES ELEVES'!A3:DQ100,35,FALSE)) -> 0 | I19: =F19+G19+H19 -> 0 | J19: =E19+I19 -> 13
A20: ='LISTE DES ELEVES'!AJ1 -> ELECTRONIQUE+ LABO | B20: =IF(I5<>"",VLOOKUP(I5,'LISTE DES ELEVES'!A3:DQ100,36,FALSE)) -> 12 | C20: =IF(I5<>"",VLOOKUP(I5,'LISTE DES ELEVES'!A3:DQ100,37,FALSE)) -> 0 | D20: =IF(I5<>"",VLOOKUP(I5,'LISTE DES ELEVES'!A3:DQ100,38,FALSE)) -> 0 | E20: =B20+C20+D20 -> 12 | F20: =IF(I5<>"",VLOOKUP(I5,'LISTE DES ELEVES'!A3:DQ100,39,FALSE)) -> 0 | G20: =IF(I5<>"",VLOOKUP(I5,'LISTE DES ELEVES'!A3:DQ100,40,FALSE)) -> 0 | H20: =IF(I5<>"",VLOOKUP(I5,'LISTE DES ELEVES'!A3:DQ100,41,FALSE)) -> 0 | I20: =F20+G20+H20 -> 0 | J20: =E20+I20 -> 12
A21: ='LISTE DES ELEVES'!AP1 -> EDUCATION PHYSIQUE | B21: =IF(I5<>"",VLOOKUP(I5,'LISTE DES ELEVES'!A3:DQ100,42,FALSE)) -> 12 | C21: =IF(I5<>"",VLOOKUP(I5,'LISTE DES ELEVES'!A3:DQ100,43,FALSE)) -> 0 | D21: =IF(I5<>"",VLOOKUP(I5,'LISTE DES ELEVES'!A3:DQ100,44,FALSE)) -> 0 | E21: =B21+C21+D21 -> 12 | F21: =IF(I5<>"",VLOOKUP(I5,'LISTE DES ELEVES'!A3:DQ100,45,FALSE)) -> 0 | G21: =IF(I5<>"",VLOOKUP(I5,'LISTE DES ELEVES'!A3:DQ100,46,FALSE)) -> 0 | H21: =IF(I5<>"",VLOOKUP(I5,'LISTE DES ELEVES'!A3:DQ100,47,FALSE)) -> 0 | I21: =F21+G21+H21 -> 0 | J21: =E21+I21 -> 12
A22: ='LISTE DES ELEVES'!AV1 -> ACTUALITE | B22: =IF(I5<>"",VLOOKUP(I5,'LISTE DES ELEVES'!A3:DQ100,48,FALSE)) -> 14 | C22: =IF(I5<>"",VLOOKUP(I5,'LISTE DES ELEVES'!A3:DQ100,49,FALSE)) -> 0 | D22: =IF(I5<>"",VLOOKUP(I5,'LISTE DES ELEVES'!A3:DQ100,50,FALSE)) -> 0 | E22: =B22+C22+D22 -> 14 | F22: =IF(I5<>"",VLOOKUP(I5,'LISTE DES ELEVES'!A3:DQ100,51,FALSE)) -> 0 | G22: =IF(I5<>"",VLOOKUP(I5,'LISTE DES ELEVES'!A3:DQ100,52,FALSE)) -> 0 | H22: =IF(I5<>"",VLOOKUP(I5,'LISTE DES ELEVES'!A3:DQ100,53,FALSE)) -> 0 | I22: =F22+G22+H22 -> 0 | J22: =E22+I22 -> 14
A23: ='LISTE DES ELEVES'!BB1 -> INSTRUMENTS | B23: =IF(I5<>"",VLOOKUP(I5,'LISTE DES ELEVES'!A3:DQ100,54,FALSE)) -> 13 | C23: =IF(I5<>"",VLOOKUP(I5,'LISTE DES ELEVES'!A3:DQ100,55,FALSE)) -> 0 | D23: =IF(I5<>"",VLOOKUP(I5,'LISTE DES ELEVES'!A3:DQ100,56,FALSE)) -> 0 | E23: =B23+C23+D23 -> 13 | F23: =IF(I5<>"",VLOOKUP(I5,'LISTE DES ELEVES'!A3:DQ100,57,FALSE)) -> 0 | G23: =IF(I5<>"",VLOOKUP(I5,'LISTE DES ELEVES'!A3:DQ100,58,FALSE)) -> 0 | H23: =IF(I5<>"",VLOOKUP(I5,'LISTE DES ELEVES'!A3:DQ100,59,FALSE)) -> 0 | I23: =F23+G23+H23 -> 0 | J23: =E23+I23 -> 13
A24: ='LISTE DES ELEVES'!BH1 -> RESISTANCE DE MATERIAUX | B24: =IF(I5<>"",VLOOKUP(I5,'LISTE DES ELEVES'!A3:DQ100,60,FALSE)) -> 7 | C24: =IF(I5<>"",VLOOKUP(I5,'LISTE DES ELEVES'!A3:DQ100,61,FALSE)) -> 0 | D24: =IF(I5<>"",VLOOKUP(I5,'LISTE DES ELEVES'!A3:DQ100,62,FALSE)) -> 0 | E24: =B24+C24+D24 -> 7 | F24: =IF(I5<>"",VLOOKUP(I5,'LISTE DES ELEVES'!A3:DQ100,63,FALSE)) -> 0 | G24: =IF(I5<>"",VLOOKUP(I5,'LISTE DES ELEVES'!A3:DQ100,64,FALSE)) -> 0 | H24: =IF(I5<>"",VLOOKUP(I5,'LISTE DES ELEVES'!A3:DQ100,65,FALSE)) -> 0 | I24: =F24+G24+H24 -> 0 | J24: =E24+I24 -> 7
E25: =B25+C25+D25 -> 0 | I25: =F25+G24+H25 -> 0 | J25: =E25+I25 -> 0
E26: =B26+C26+D26 -> 0 | I26: =F26+G25+H26 -> 0 | J26: =E26+I26 -> 0
E27: =B27+C27+D27 -> 0 | I27: =F27+G26+H27 -> 0 | J27: =E27+I27 -> 0
E28: =B28+C28+D28 -> 0 | I28: =F28+G27+H28 -> 0 | J28: =E28+I28 -> 0
A29: MAXIMA | B29: 40 | C29: 40 | D29: 80 | E29: 160 | F29: 40 | G29: 40 | H29: 80 | I29: 160 | J29: 320
A30: ='LISTE DES ELEVES'!BN1 -> DESSIN D'ELECTRIICITE | B30: =IF(I5<>"",VLOOKUP(I5,'LISTE DES ELEVES'!A3:DQ100,66,FALSE)) -> 32 | C30: =IF(I5<>"",VLOOKUP(I5,'LISTE DES ELEVES'!A3:DQ100,67,FALSE)) -> 0 | D30: =IF(I5<>"",VLOOKUP(I5,'LISTE DES ELEVES'!A3:DQ100,68,FALSE)) -> 0 | E30: =B30+C30+D30 -> 32 | F30: =IF(I5<>"",VLOOKUP(I5,'LISTE DES ELEVES'!A3:DQ100,69,FALSE)) -> 0 | G30: =IF(I5<>"",VLOOKUP(I5,'LISTE DES ELEVES'!A3:DQ100,70,FALSE)) -> 0 | H30: =IF(I5<>"",VLOOKUP(I5,'LISTE DES ELEVES'!A3:DQ100,71,FALSE)) -> 0 | I30: =F30+G30+H30 -> 0 | J30: =E30+I30 -> 32
E31: =B31+C31+D31 -> 0 | I31: =F31+G30+H31 -> 0 | J31: =E31+I31 -> 0
A32: ='LISTE DES ELEVES'!BT1 -> ELECTRICITE GENERALE | B32: =IF(I5<>"",VLOOKUP(I5,'LISTE DES ELEVES'!A3:DQ100,72,FALSE)) -> 36 | C32: =IF(I5<>"",VLOOKUP(I5,'LISTE DES ELEVES'!A3:DQ100,73,FALSE)) -> 0 | D32: =IF(I5<>"",VLOOKUP(I5,'LISTE DES ELEVES'!A3:DQ100,74,FALSE)) -> 0 | E32: =B32+C32+D32 -> 36 | F32: =IF(I5<>"",VLOOKUP(I5,'LISTE DES ELEVES'!A3:DQ100,75,FALSE)) -> 0 | G32: =IF(I5<>"",VLOOKUP(I5,'LISTE DES ELEVES'!A3:DQ100,76,FALSE)) -> 0 | H32: =IF(I5<>"",VLOOKUP(I5,'LISTE DES ELEVES'!A3:DQ100,77,FALSE)) -> 0 | I32: =F32+G31+H32 -> 0 | J32: =E32+I32 -> 36
A33: ='LISTE DES ELEVES'!BZ1 -> MACHINES ELECTRIQUES | B33: =IF(I5<>"",VLOOKUP(I5,'LISTE DES ELEVES'!A3:DQ100,78,FALSE)) -> 30 | C33: =IF(I5<>"",VLOOKUP(I5,'LISTE DES ELEVES'!A3:DQ100,79,FALSE)) -> 0 | D33: =IF(I5<>"",VLOOKUP(I5,'LISTE DES ELEVES'!A3:DQ100,80,FALSE)) -> 0 | E33: =B33+C33+D33 -> 30 | F33: =IF(I5<>"",VLOOKUP(I5,'LISTE DES ELEVES'!A3:DQ100,81,FALSE)) -> 0 | G33: =IF(I5<>"",VLOOKUP(I5,'LISTE DES ELEVES'!A3:DQ100,82,FALSE)) -> 0 | H33: =IF(I5<>"",VLOOKUP(I5,'LISTE DES ELEVES'!A3:DQ100,83,FALSE)) -> 0 | I33: =F33+G32+H33 -> 0 | J33: =E33+I33 -> 30
A34: ='LISTE DES ELEVES'!CF1 -> TECHNO-ELECTRICITE | B34: =IF(I5<>"",VLOOKUP(I5,'LISTE DES ELEVES'!A3:DQ100,84,FALSE)) -> 24 | C34: =IF(I5<>"",VLOOKUP(I5,'LISTE DES ELEVES'!A3:DQ100,85,FALSE)) -> 0 | D34: =IF(I5<>"",VLOOKUP(I5,'LISTE DES ELEVES'!A3:DQ100,86,FALSE)) -> 0 | E34: =B34+C34+D34 -> 24 | F34: =IF(I5<>"",VLOOKUP(I5,'LISTE DES ELEVES'!A3:DQ100,87,FALSE)) -> 0 | G34: =IF(I5<>"",VLOOKUP(I5,'LISTE DES ELEVES'!A3:DQ100,88,FALSE)) -> 0 | H34: =IF(I5<>"",VLOOKUP(I5,'LISTE DES ELEVES'!A3:DQ100,89,FALSE)) -> 0 | I34: =F34+G33+H34 -> 0 | J34: =E34+I34 -> 24
E35: =B35+C35+D35 -> 0 | I35: =F35+G34+H35 -> 0 | J35: =E35+I35 -> 0
E36: =B36+C36+D36 -> 0 | I36: =F36+G35+H36 -> 0 | J36: =E36+I36 -> 0
A37: MAXIMA | B37: 50 | C37: 50 | D37: 100 | E37: 200 | F37: 50 | G37: 50 | H37: 100 | I37: 200 | J37: 400
A38: ='LISTE DES ELEVES'!CL1 -> FRANCAIS | B38: =IF(I5<>"",VLOOKUP(I5,'LISTE DES ELEVES'!A3:DQ100,90,FALSE)) -> 25 | C38: =IF(I5<>"",VLOOKUP(I5,'LISTE DES ELEVES'!A3:DQ100,91,FALSE)) -> 0 | D38: =IF(I5<>"",VLOOKUP(I5,'LISTE DES ELEVES'!A3:DQ100,92,FALSE)) -> 0 | E38: =B38+C38+D38 -> 25 | F38: =IF(I5<>"",VLOOKUP(I5,'LISTE DES ELEVES'!A3:DQ100,93,FALSE)) -> 0 | G38: =IF(I5<>"",VLOOKUP(I5,'LISTE DES ELEVES'!A3:DQ100,94,FALSE)) -> 0 | H38: =IF(I5<>"",VLOOKUP(I5,'LISTE DES ELEVES'!A3:DQ100,95,FALSE)) -> 0 | I38: =F38+G38+H38 -> 0 | J38: =E38+I38 -> 25
A39: ='LISTE DES ELEVES'!CR1 -> MATHEMATIQUE | B39: =IF(I5<>"",VLOOKUP(I5,'LISTE DES ELEVES'!A3:DQ100,96,FALSE)) -> 29 | C39: =IF(I5<>"",VLOOKUP(I5,'LISTE DES ELEVES'!A3:DQ100,97,FALSE)) -> 0 | D39: =IF(I5<>"",VLOOKUP(I5,'LISTE DES ELEVES'!A3:DQ100,98,FALSE)) -> 0 | E39: =B39+C39+D39 -> 29 | F39: =IF(I5<>"",VLOOKUP(I5,'LISTE DES ELEVES'!A3:DQ100,99,FALSE)) -> 0 | G39: =IF(I5<>"",VLOOKUP(I5,'LISTE DES ELEVES'!A3:DQ100,100,FALSE)) -> 0 | H39: =IF(I5<>"",VLOOKUP(I5,'LISTE DES ELEVES'!A3:DQ100,101,FALSE)) -> 0 | I39: =F39+G39+H39 -> 0 | J39: =E39+I39 -> 29
A41: MAXIMA | B41: 100 | C41: 100 | E41: 200 | F41: 100 | G41: 100 | I41: 200 | J41: 400
...

Sheet LISTE DES ELEVES
A1: NOM ET POST-NOM | B1: SEXE | C1: LIEU ET DATE DE NAISSANCE | D1: CLASSE | E1: ECOLE | F1: RELIGION | L1: CIVISME | R1: EDUCATION A LA VIE | X1: ANGLAIS | AD1: INFORMATIQUE | AJ1: ELECTRONIQUE+ LABO | AP1: EDUCATION PHYSIQUE | AV1: ACTUALITE | BB1: INSTRUMENTS | BH1: RESISTANCE DE MATERIAUX | BN1: DESSIN D'ELECTRIICITE | BT1: ELECTRICITE GENERALE | BZ1: MACHINES ELECTRIQUES | CF1: TECHNO-ELECTRICITE | CL1: FRANCAIS | CR1: MATHEMATIQUE | CX1: Atelier Electricite | DB1: Labo Electrique
F2: 1er P10 | G2: 2è P 10 | H2: EX20 | I2: 3èP10 | J2: 4èP10 | K2: EX20 | L2: 1er P10 | M2: 2è P 10 | N2: EX20 | O2: 3èP10 | P2: 4èP10 | Q2: EX20 | R2: 1er P10 | S2: 2è P 10 | T2: EX20 | U2: 3èP10 | V2: 4èP10 | W2: EX20 | X2: 1er P20 | Y2: 2è P 20 | Z2: EX40 | AA2: 3èP20 | AB2: 4èP20 | AC2: EX40 | AD2: 1er P20 | AE2: 2è P 20 | AF2: EX40 | AG2: 3èP20 | AH2: 4èP20 | AI2: EX40 | AJ2: 1er P20 | AK2: 2è P 20 | AL2: EX40 | AM2: 3èP20 | AN2: 4èP20 | AO2: EX40 | AP2: 1er P20 | AQ2: 2è P 20 | AR2: EX40 | AS2: 3èP20 | AT2: 4èP20 | AU2: EX40 | AV2: 1er P20 | AW2: 2è P 20 | AX2: EX40 | AY2: 3èP20 | AZ2: 4èP20 | BA2: EX40 | BB2: 1er P20 | BC2: 2è P 20 | BD2: EX40 | BE2: 3èP20 | BF2: 4èP20 | BG2: EX40 | BH2: 1er P20 | BI2: 2è P 20 | BJ2: EX40 | BK2: 3èP20 | BL2: 4èP20 | BM2: EX40 | BN2: 1er P40 | BO2: 2è P 40 | BP2: EX80 | BQ2: 3èP40 | BR2: 4èP40 | BS2: EX80 | BT2: 1er P40 | BU2: 2è P 40 | BV2: EX80 | BW2: 3èP40 | BX2: 4èP40 | BY2: EX80 | BZ2: 1er P40 | CA2: 2è P 40 | CB2: EX80 | CC2: 3èP40 | CD2: 4èP40 | CE2: EX80 | CF2: 1er P40 | CG2: 2è P 40 | CH2: EX80 | CI2: 3èP40 | CJ2: 4èP40 | CK2: EX80 | CL2: 1er P50 | CM2: 2è P 50 | CN2: EX100 | CO2: 3èP50 | CP2: 4èP50 | CQ2: EX100 | CR2: 1er P50 | CS2: 2è P 50 | CT2: EX100 | CU2: 3èP50 | CV2: 4èP50 | CW2: EX100 | CX2: 1er P100 | CY2: 2è P 100 | CZ2: 3èP100 | DA2: 4èP100 | DB2: 1er P100 | DC2: 2è P 100 | DD2: 3èP100 | DE2: 4èP100
A3: EBGOLO NGOLA | B3: M | C3: BANDUNDU, Le 21/3/2009 | D3: 3ème ELELECT | E3: ITP MOSALA | F3: 5 | L3: 5 | R3: 6 | X3: 10 | AD3: 8 | AJ3: 8 | AP3: 4 | AV3: 5 | BB3: 9 | BH3: 6 | BN3: 20 | BT3: 23 | BZ3: 19 | CL3: 23 | CR3: 32 | CX3: 60 | DB3: 60
A4: ILUNGA LUNGILA | B4: M | C4: KINSHASA, Le 09/09/2008 | D4: 3ème ELELECT | E4: ITP MOSALA | F4: 5 | AP4: 4 | AV4: 4 | DB4: 60
A5: IZEY KAYIBA | B5: M | C5: KINSHASA, Le 09/09/2008 | D5: 3ème ELELECT | E5: ITP MOSALA | F5: 3 | L5: 5 | R5: 7 | X5: 4 | AD5: 10 | AJ5: 12 | AP5: 5 | AV5: 13 | BN5: 13 | BZ5: 16 | CL5: 22 | CR5: 15 | CX5: 60 | DB5: 60
A6: KAPALATI MAYIMI | B6: M | C6: BANDUNDU,Le 23/07/2007 | D6: 3ème ELELECT | E6: ITP MOSALA | F6: 3 | L6: 4 | R6: 6 | X6: 13 | AD6: 13 | AJ6: 12 | AP6: 12 | AV6: 14 | BB6: 13 | BH6: 7 | BN6: 32 | BT6: 36 | BZ6: 30 | CF6: 24 | CL6: 25 | CR6: 29 | CX6: 60 | DB6: 60
A7: KIANGEBENI MBUTA | B7: M | C7: KINSHASA,Le 11/02/2009 | D7: 3ème ELELECT | E7: ITP MOSALA | F7: 3 | L7: 8 | R7: 8 | X7: 19 | AD7: 13 | AJ7: 17 | AP7: 11 | AV7: 8 | BB7: 16 | BH7: 17 | BN7: 36 | BT7: 36 | BZ7: 40 | CF7: 30 | CL7: 40 | CR7: 41 | CX7: 60 | DB7: 60
A8: KIBWILA MBO | B8: M | D8: 3ème ELELECT | E8: ITP MOSALA | F8: 6 | L8: 5 | R8: 7 | X8: 4 | AD8: 8 | AP8: 4 | AV8: 9 | CF8: 24 | CL8: 25 | CR8: 25 | CX8: 60 | DB8: 60
A9: KILOLO FALANGA | B9: M | C9: KIKWIT, Le 16/08/2008 | D9: 3ème ELELECT | E9: ITP MOSALA | F9: 5 | L9: 3 | R9: 7 | X9: 6 | AD9: 8 | AJ9: 10 | AP9: 6 | AV9: 13 | BB9: 10 | BN9: 7 | BZ9: 23 | CF9: 20 | CL9: 23 | CR9: 26 | CX9: 60 | DB9: 60
A10: KIMBE MANKUKU | B10: M | C10: KINSHASA,Le 05/04/2009 | D10: 3ème ELELECT | E10: ITP MOSALA | F10: 3 | L10: 4 | R10: 7 | X10: 13 | AD10: 8 | AJ10: 10 | AP10: 7 | AV10: 13 | BB10: 10 | BH10: 7 | BN10: 26 | BT10: 20 | BZ10: 22 | CF10: 24 | CL10: 25 | CR10: 28 | CX10: 60 | DB10: 60
A11: KINIADI MBO | B11: M | C11: BANDUNDU,Le 28/03/2009 | D11: 3ème ELELECT | E11: ITP MOSALA | F11: 5 | L11: 5 | R11: 6 | X11: 19 | AD11: 9 | AJ11: 18 | AP11: 11 | AV11: 10 | BB11: 12 | BH11: 9 | BN11: 27 | BT11: 28 | BZ11: 24 | CF11: 26 | CL11: 30 | CR11: 35 | CX11: 60 | DB11: 60
A12: KIPWELE KAMBAY | B12: M | C12: BANDUNDU,Le 15/08/2008 | D12: 3ème ELELECT | E12: ITP MOSALA | F12: 6 | L12: 3 | R12: 7 | X12: 8 | AD12: 9 | AJ12: 10 | AP12: 10 | AV12: 13 | BB12: 11 | BH12: 19 | BN12: 20 | BT12: 18 | BZ12: 22 | CF12: 22 | CL12: 21 | CR12: 32 | CX12: 60 | DB12: 60
A13: KISANGALA DAGWIDA | B13: M | C13: MAKINGA , Le 14/11/2006 | D13: 3ème ELELECT | E13: ITP MOSALA | F13: 6 | L13: 6 | R13: 7 | X13: 13 | AD13: 12 | AJ13: 12 | AP13: 8 | AV13: 10 | BB13: 13 | BH13: 5 | BN13: 19 | BZ13: 21 | CF13: 29 | CL13: 32 | CR13: 30 | CX13: 60 | DB13: 60
A14: KIYE BENGA | B14: M | C14: BANDUNDU,Le 06/09/2008 | D14: 3ème ELELECT | E14: ITP MOSALA | F14: 5 | L14: 4 | R14: 7 | X14: 5 | AD14: 9 | AJ14: 6 | AP14: 10 | AV14: 10 | BB14: 9 | BN14: 20 | BT14: 16 | BZ14: 21 | CF14: 20 | CR14: 39 | CX14: 60 | DB14: 60
A15: KUTAMEKA MAVON | B15: M | C15: BANDUNDU,Le 10/08/2008 | D15: 3ème ELELECT | E15: ITP MOSALA | F15: 5 | L15: 4 | R15: 6 | X15: 4 | AD15: 8 | AJ15: 11 | AP15: 4 | AV15: 5 | BB15: 9 | BH15: 13 | BN15: 14 | BZ15: 22 | CF15: 20 | CL15: 27 | CR15: 31 | CX15: 60 | DB15: 60
A16: LUBIY BASALEME | B16: M | C16: BANDUNDU,Le 06/09/2008 | D16: 3ème ELELECT | E16: ITP MOSALA | F16: 6 | L16: 5 | R16: 6 | X16: 9 | AD16: 10 | AJ16: 11 | AP16: 10 | AV16: 12 | BB16: 13 | BN16: 21 | BT16: 29 | BZ16: 22 | CF16: 22 | CL16: 23 | CR16: 33 | CX16: 60 | DB16: 60
A17: MABANZA NDUKUMESA | B17: M | C17: BANDUNDU,Le 17/03/2009 | D17: 3ème ELELECT | E17: ITP MOSALA | F17: 6 | L17: 5 | R17: 6 | X17: 9 | AD17: 11 | AJ17: 10 | AP17: 10 | AV17: 7 | BB17: 12 | BH17: 15 | BN17: 17 | BT17: 32 | BZ17: 21 | CF17: 20 | CL17: 21 | CR17: 28 | CX17: 60 | DB17: 60
A18: MABRIKI NGAMUZOLO | B18: M | C18: BANDUNDU,Le 06/09/2008 | D18: 3ème ELELECT | E18: ITP MOSALA | F18: 6 | R18: 6 | X18: 4 | AD18: 9 | AP18: 5 | AV18: 10 | BB18: 11 | BN18: 6 | CF18: 22 | CR18: 31 | CX18: 60 | DB18: 60
A19: MABULUKI VINCENT | B19: M | C19: BANDUNDU,Le 06/09/2008 | D19: 3ème ELELECT | E19: ITP MOSALA | F19: 3 | L19: 4 | R19: 6 | X19: 12 | AD19: 11 | AJ19: 13 | AP19: 12 | AV19: 8 | BB19: 12 | BN19: 33 | BT19: 30 | BZ19: 23 | CF19: 26 | CL19: 34 | CR19: 30 | CX19: 60 | DB19: 60
A20: MAFUTA MUKUNI | B20: M | C20: BANDUNDU,Le 21/02/2010 | D20: 3ème ELELECT | E20: ITP MOSALA | F20: 3 | L20: 4 | R20: 7 | X20: 5 | AD20: 8 | AJ20: 12 | AP20: 10 | AV20: 14 | BB20: 12 | BN20: 20 | BT20: 18 | BZ20: 20 | CF20: 22 | CL20: 25 | CR20: 25 | CX20: 60 | DB20: 60
A21: MAKIA MEFI | B21: M | C21: MBAMPUTU,Le 04/12/2008 | D21: 3ème ELELECT | E21: ITP MOSALA | F21: 5 | L21: 6 | R21: 7 | X21: 10 | AD21: 13 | AJ21: 11 | AP21: 9 | AV21: 11 | BB21: 12 | BH21: 5 | BN21: 24 | BT21: 25 | BZ21: 23 | CF21: 21 | CL21: 30 | CR21: 15 | CX21: 60 | DB21: 60
A22: MAKONO LINGIS | B22: M | C22: BOKALA,Le 27/07/2009 | D22: 3ème ELELECT | E22: ITP MOSALA | F22: 6 | L22: 5 | R22: 7 | X22: 7 | AD22: 10 | AJ22: 6 | AP22: 10 | AV22: 10 | BB22: 11 | BH22: 7 | BT22: 26 | BZ22: 21 | CF22: 22 | CL22: 38 | CR22: 27 | CX22: 60 | DB22: 60
A23: MAMER LINGILINGI | B23: M | C23: KIZIER Le 30/06/2008 | D23: 3ème ELELECT | E23: ITP MOSALA | F23: 3 | L23: 5 | R23: 7 | X23: 16 | AD23: 10 | AJ23: 12 | AP23: 7 | AV23: 12 | BB23: 8 | BH23: 4 | BN23: 20 | BT23: 25 | BZ23: 17 | CF23: 20 | CL23: 20 | CR23: 28 | CX23: 60 | DB23: 60
A24: MANGANTIEME MPIA | B24: M | C24: BANDUNDU,Le | D24: 3ème ELELECT | E24: ITP MOSALA | F24: 6 | L24: 5 | R24: 6 | X24: 5 | AD24: 10 | AJ24: 6 | AP24: 10 | AV24: 8 | BB24: 11 | BH24: 10 | BN24: 13 | BT24: 14 | BZ24: 22 | CF24: 22 | CL24: 19 | CR24: 33 | CX24: 60 | DB24: 60
A25: MANGOLONGOLO IFUNGU | B25: M | C25: BANDUNDU,Le 05/07/2007 | D25: 3ème ELELECT | E25: ITP MOSALA | F25: 5 | L25: 4 | R25: 7 | X25: 14 | AD25: 9 | AJ25: 9 | AP25: 10 | AV25: 8 | BB25: 10 | BH25: 3 | BN25: 18 | BT25: 24 | BZ25: 21 | CF25: 24 | CL25: 25 | CR25: 29 | CX25: 60 | DB25: 60
A26: MATUNGULU ETURANGWI | B26: M | C26: BANDUNDU,Le 06/07/2008 | D26: 3ème ELELECT | E26: ITP MOSALA | F26: 6 | L26: 3 | R26: 7 | X26: 11 | AD26: 8 | AJ26: 11 | AP26: 5 | AV26: 11 | BB26: 8 | BH26: 19 | BN26: 15 | BT26: 20 | BZ26: 18 | CF26: 16 | CL26: 22 | CR26: 29 | CX26: 60 | DB26: 60
A27: MAWETE MOKE | B27: M | C27: BANDUNDU,Le | D27: 3ème ELELECT | E27: ITP MOSALA | F27: 3 | L27: 5 | R27: 8 | X27: 5 | AD27: 5 | AJ27: 4 | AP27: 5 | AV27: 7 | BB27: 8 | BH27: 6 | BN27: 21 | BZ27: 21 | CF27: 14 | CL27: 22 | CR27: 29 | CX27: 60 | DB27: 60
A28: MAYAMA MBO | B28: M | C28: BANDUNDU,Le 22/12/2008 | D28: 3ème ELELECT | E28: ITP MOSALA | F28: 6 | L28: 5 | R28: 7 | X28: 12 | AD28: 9 | AP28: 7 | AV28: 4 | BB28: 10 | BH28: 5 | BN28: 13 | BT28: 27 | CF28: 23 | CL28: 21 | CR28: 31 | CX28: 60 | DB28: 60
A29: MAYENDE MONSENGO | B29: M | C29: ISAKA,Le 13/08/2007 | D29: 3ème ELELECT | E29: ITP MOSALA | F29: 3 | L29: 6 | R29: 6 | X29: 4 | AD29: 11 | AJ29: 11 | AP29: 10 | AV29: 7 | BB29: 13 | BH29: 3 | BN29: 20 | BZ29: 23 | CF29: 28 | CL29: 25 | CR29: 37 | CX29: 60 | DB29: 60
A30: MBALANDA TANDWA | B30: M | C30: BANDUNDU,Le 23/08/2008 | D30: 3ème ELELECT | E30: ITP MOSALA | F30: 5 | L30: 5 | R30: 7 | X30: 4 | AD30: 8 | AP30: 5 | AV30: 12 | BN30: 11 | CF30: 22 | CL30: 22 | CR30: 19 | CX30: 60 | DB30: 60
A31: MBILAYAMA NTANTU | B31: M | C31: BANDUNDU,Le 23/10/2008 | D31: 3ème ELELECT | E31: ITP MOSALA | F31: 5 | L31: 6 | R31: 7 | X31: 9 | AD31: 8 | AJ31: 10 | AP31: 10 | AV31: 8 | BB31: 12 | BH31: 8 | BN31: 26 | BT31: 26 | BZ31: 26 | CF31: 30 | CL31: 25 | CR31: 15 | CX31: 60 | DB31: 60
A32: MBULU BIMA | B32: M | C32: BANDUNDU,Le 22/06/2008 | D32: 3ème ELELECT | E32: ITP MOSALA | F32: 3 | L32: 3 | R32: 6 | X32: 15 | AD32: 8 | AP32: 10 | AV32: 10 | BB32: 9 | BH32: 6 | BN32: 16 | BZ32: 32 | CL32: 21 | CR32: 35 | CX32: 60 | DB32: 60
A33: MBUNDI KAKUDI | B33: M | C33: MBWASA,Le 26/05/2008 | D33: 3ème ELELECT | E33: ITP MOSALA | L33: 6 | R33: 7 | X33: 14 | AD33: 11 | AJ33: 11 | AP33: 10 | AV33: 8 | BB33: 13 | BH33: 7 | BN33: 17 | BT33: 32 | BZ33: 29 | CF33: 22 | CL33: 29 | CR33: 34 | CX33: 60 | DB33: 60
A34: MBUYULU MUNGANZA | B34: M | C34: BANDUNDU,Le 18/04/2009 | D34: 3ème ELELECT | E34: ITP MOSALA | L34: 5 | R34: 7 | X34: 6 | AD34: 10 | AJ34: 10 | AP34: 10 | AV34: 11 | BB34: 10 | BH34: 5 | BN34: 16 | BZ34: 29 | CF34: 25 | CL34: 25 | CR34: 31 | CX34: 60 | DB34: 60
A35: MIKWIBI KABANGU | B35: M | C35: MUSHIE,Le 03/09/2007 | D35: 3ème ELELECT | E35: ITP MOSALA | F35: 5 | L35: 5 | R35: 7 | X35: 12 | AD35: 9 | AJ35: 12 | AP35: 10 | AV35: 11 | BB35: 13 | BH35: 7 | BN35: 25 | BT35: 23 | BZ35: 26 | CF35: 22 | CL35: 26 | CR35: 31 | CX35: 60 | DB35: 60
A36: MPAKASA NDELA | B36: F | C36: BANDUNDU,Le 11/07/2009 | D36: 3ème ELELECT | E36: ITP MOSALA | F36: 7 | L36: 5 | R36: 8 | X36: 15 | AD36: 11 | AJ36: 11 | AP36: 10 | AV36: 8 | BB36: 12 | BH36: 14 | BN36: 26 | BT36: 30 | BZ36: 26 | CF36: 26 | CL36: 33 | CR36: 32 | CX36: 60 | DB36: 60
A37: MPETI NDIYO | B37: M | C37: MUSHU,Le 02/03/2010 | D37: 3ème ELELECT | E37: ITP MOSALA | F37: 3 | L37: 6 | R37: 7 | X37: 10 | AD37: 8 | AJ37: 10 | AP37: 5 | AV37: 13 | BB37: 8 | BH37: 13 | BN37: 17 | BT37: 19 | BZ37: 23 | CF37: 20 | CL37: 31 | CR37: 30 | CX37: 60 | DB37: 60
A38: MUFOLO MUZINGA | B38: M | C38: MISAY,Le 17/11/2009 | D38: 3ème ELELECT | E38: ITP MOSALA | F38: 6 | L38: 4 | R38: 7 | X38: 12 | AD38: 9 | AJ38: 13 | AP38: 5 | AV38: 13 | BB38: 13 | BH38: 5 | BN38: 16 | BT38: 17 | BZ38: 20 | CF38: 26 | CL38: 22 | CR38: 30 | CX38: 60 | DB38: 60
A39: MUKATA NGIAY | B39: M | C39: BANDUNDU,Le 27/10/2007 | D39: 3ème ELELECT | E39: ITP MOSALA | L39: 5 | R39: 7 | X39: 11 | AD39: 12 | AJ39: 12 | AP39: 10 | AV39: 3 | BB39: 12 | BH39: 5 | BN39: 16 | BT39: 24 | BZ39: 19 | CF39: 22 | CL39: 21 | CR39: 30 | CX39: 60 | DB39: 60
A40: MUNDENDE LUYINDULA | B40: M | C40: BANDUNDU,Le 27/10/2008 | D40: 3ème ELELECT | E40: ITP MOSALA | F40: 5 | L40: 5 | R40: 7 | X40: 17 | AD40: 11 | AP40: 5 | AV40: 5 | BB40: 12 | BN40: 26 | CF40: 28 | CL40: 35 | CR40: 32 | CX40: 60 | DB40: 60
...

Sheet Feuil3
A1: ITP MOSALA
A2: BP : 213
A3: BANDUNDU
A4: NOM ET POST-NOM : | B4: =Feuil1!I5 -> KAPALATI MAYIMI
A5: =Feuil1!G7 -> 3ème ELELECT | B5: PREMIER SEMESTRE
A6: Branches | B6: TR. JOUR | D6: Compo | E6: TOT
B7: MAX | C7: 1ère p | D7: sition
A8: MAXIMA
A9: =Feuil1!A14 -> RELIGION | B9: 10 | C9: =Feuil1!B14 -> 3
A10: =Feuil1!A15 -> CIVISME | B10: 10 | C10: =Feuil1!B15 -> 4
A11: =Feuil1!A16 -> EDUCATION A LA VIE | B11: 10 | C11: =Feuil1!B16 -> 6
A12: =Feuil1!A18 -> ANGLAIS | B12: 20 | C12: =Feuil1!B18 -> 13
A13: =Feuil1!A19 -> INFORMATIQUE | B13: 20 | C13: =Feuil1!B19 -> 13
A14: =Feuil1!A20 -> ELECTRONIQUE+ LABO | B14: 20 | C14: =Feuil1!B20 -> 12
A15: =Feuil1!A21 -> EDUCATION PHYSIQUE | B15: 20 | C15: =Feuil1!B21 -> 12
A16: =Feuil1!A22 -> ACTUALITE | B16: 20 | C16: =Feuil1!B22 -> 14
A17: =Feuil1!A23 -> INSTRUMENTS | B17: 20 | C17: =Feuil1!B23 -> 13
A18: =Feuil1!A24 -> RESISTANCE DE MATERIAUX | B18: 20 | C18: =Feuil1!B24 -> 7
A19: =Feuil1!A30 -> DESSIN D'ELECTRIICITE | B19: 40 | C19: =Feuil1!B30 -> 32
A20: =Feuil1!A32 -> ELECTRICITE GENERALE | B20: 40 | C20: =Feuil1!B32 -> 36
A21: =Feuil1!A33 -> MACHINES ELECTRIQUES | B21: 40 | C21: =Feuil1!B33 -> 30
A22: =Feuil1!A34 -> TECHNO-ELECTRICITE | B22: 40 | C22: =Feuil1!B34 -> 24
A23: =Feuil1!A38 -> FRANCAIS | B23: 50 | C23: =Feuil1!B38 -> 25
A24: =Feuil1!A39 -> MATHEMATIQUE | B24: 50 | C24: =Feuil1!B39 -> 29
A25: =Feuil1!A42 -> Atelier Electricite | B25: 100 | C25: =Feuil1!B42 -> 60
A26: =Feuil1!A43 -> Labo Electrique | B26: 100 | C26: =Feuil1!B43 -> 60
A27: MAXIMA GENERAUX | B27: =Feuil1!B44 -> 630
A28: TOTAUX | C28: =Feuil1!B45 -> 393
A29: APPLICATION
A30: CONDUITE
A31: POURCENTAGE | C31: =Feuil1!B46 -> 62.380952

Sheet Feuil2
